Workbook

Sheet Dashboard
B1: Property Management Tracker — Live Dashboard
B2: Auto-calculated from PM ONLY, LEASE ONLY, and Len-Onboarded — all figures are live formulas that update when source rows change.
B4: Report Date (auto) | C4: =TODAY() -> 46253
B5: GST Rate (assumption, used for estimates below) | C5: 0.05 | D5: Input cell — edit if GST rate changes. PM ONLY's own 'TOTAL FEES WITH GST' column is blank in the source data, so this rate is used to estimate GST-inclusive management-fee revenue below.
B6: Heartbeat (auto-refresh timestamp) | D6: Written by an external scheduler (e.g. n8n) on a timer. Google Sheets only recalculates TODAY()-based formulas (the Leasing Pipeline and Growth sections) on open, on edit, or on its own periodic auto-recalc — writing any value here counts as an edit and forces a full recalculation, so those KPIs stay fresh even if no human opens the sheet. Named range: Heartbeat_Cell.
B7: 1. Portfolio Overview
B8: Metric | C8: Value | D8: Notes
B9: Total Units Tracked (PM ONLY) | C9: =COUNTA('PM ONLY'!D2:D2000) -> 229 | D9: Count of non-blank Property rows in PM ONLY.
B10: Active Units | C10: =COUNTIF('PM ONLY'!I2:I2000,"Active") -> 216
B11: Terminated Units | C11: =COUNTIF('PM ONLY'!I2:I2000,"Terminated") -> 12
B12: Occupied Units | C12: =COUNTIF('PM ONLY'!H2:H2000,"Occupied") -> 170
B13: Vacant Units | C13: =COUNTIF('PM ONLY'!H2:H2000,"Vacant") -> 54
B14: Take Over (in transition) Units | C14: =COUNTIF('PM ONLY'!H2:H2000,"Take over") -> 3 | D14: "Take over" is a third Occupancy Status value found in the source data, distinct from Occupied/Vacant.
B15: Occupancy Rate (Occupied ÷ Occupied+Vacant+Take Over) | C15: =IFERROR(C12/(C12+C13+C14),0) -> 0.74889868 | D15: Guarded against a zero denominator.
B17: Units by Assigned PM (workload)
B18: Assigned PM | C18: Active Units | D18: Total Units (incl. Terminated) | E18: % of Active Portfolio
B19: Thomas Bruchig | C19: =COUNTIFS('PM ONLY'!F2:F2000,$B19,'PM ONLY'!I2:I2000,"Active") -> 97 | D19: =COUNTIF('PM ONLY'!F2:F2000,$B19) -> 97 | E19: =IFERROR(C19/$C$10,0) -> 0.44907407
B20: Junny Ko | C20: =COUNTIFS('PM ONLY'!F2:F2000,$B20,'PM ONLY'!I2:I2000,"Active") -> 38 | D20: =COUNTIF('PM ONLY'!F2:F2000,$B20) -> 47 | E20: =IFERROR(C20/$C$10,0) -> 0.17592593
B21: Ranjeet Bhangu | C21: =COUNTIFS('PM ONLY'!F2:F2000,$B21,'PM ONLY'!I2:I2000,"Active") -> 42 | D21: =COUNTIF('PM ONLY'!F2:F2000,$B21) -> 42 | E21: =IFERROR(C21/$C$10,0) -> 0.19444444
B22: Hemi Persaud | C22: =COUNTIFS('PM ONLY'!F2:F2000,$B22,'PM ONLY'!I2:I2000,"Active") -> 26 | D22: =COUNTIF('PM ONLY'!F2:F2000,$B22) -> 26 | E22: =IFERROR(C22/$C$10,0) -> 0.12037037
B23: Lorraine Girouard | C23: =COUNTIFS('PM ONLY'!F2:F2000,$B23,'PM ONLY'!I2:I2000,"Active") -> 8 | D23: =COUNTIF('PM ONLY'!F2:F2000,$B23) -> 9 | E23: =IFERROR(C23/$C$10,0) -> 0.037037037
B24: Emman Lim | C24: =COUNTIFS('PM ONLY'!F2:F2000,$B24,'PM ONLY'!I2:I2000,"Active") -> 3 | D24: =COUNTIF('PM ONLY'!F2:F2000,$B24) -> 3 | E24: =IFERROR(C24/$C$10,0) -> 0.013888889
B25: Parmeet Singh | C25: =COUNTIFS('PM ONLY'!F2:F2000,$B25,'PM ONLY'!I2:I2000,"Active") -> 1 | D25: =COUNTIF('PM ONLY'!F2:F2000,$B25) -> 3 | E25: =IFERROR(C25/$C$10,0) -> 0.0046296296
B26: Lorenzo Cabason | C26: =COUNTIFS('PM ONLY'!F2:F2000,$B26,'PM ONLY'!I2:I2000,"Active") -> 0 | D26: =COUNTIF('PM ONLY'!F2:F2000,$B26) -> 1 | E26: =IFERROR(C26/$C$10,0) -> 0
B27: Rachel Qin | C27: =COUNTIFS('PM ONLY'!F2:F2000,$B27,'PM ONLY'!I2:I2000,"Active") -> 1 | D27: =COUNTIF('PM ONLY'!F2:F2000,$B27) -> 1 | E27: =IFERROR(C27/$C$10,0) -> 0.0046296296
B29: 2. Revenue Snapshot
B30: Metric | C30: Value | D30: Notes
B31: Total Monthly Rent Roll (PM ONLY) | C31: =SUM('PM ONLY'!P2:P2000) -> 249643
B32: Total Monthly Rent Roll (LEASE ONLY, supplemental) | C32: =SUM('LEASE ONLY'!M2:M1000) -> 5480 | D32: Leasing-only engagements; kept separate so it is not double-counted with PM ONLY rent.
B33: Total Management Fee Revenue, excl. GST (PM ONLY) | C33: =SUM('PM ONLY'!U2:U2000) -> 12623.675
B34: Total Management Fee Revenue, incl. GST (estimated) | C34: =C33*(1+$C$5) -> 13254.859 | D34: Estimated using the GST Rate assumption above — PM ONLY's 'TOTAL FEES WITH GST' column has no source formula/values to sum directly.
B35: Total Leasing Fee Revenue, excl. GST (PM ONLY) | C35: =SUM('PM ONLY'!O2:O2000) -> 85458
B36: Total Leasing Fee Revenue, incl. GST (LEASE ONLY) | C36: =SUM('LEASE ONLY'!Q2:Q1000) -> 11957.4 | D36: LEASE ONLY column Q already computes Leasing Fee x 1.05 per row in the source.
B37: Total Owner Disbursements (PM ONLY) | C37: =SUM('PM ONLY'!X2:X2000) -> 221171.27
B38: Total Owner Disbursements (LEASE ONLY) | C38: =SUM('LEASE ONLY'!S2:S1000) -> -6377.4
B39: Combined Total Owner Disbursements | C39: =C37+C38 -> 214793.87
B40: Ancillary Income — Pet Fee (PM ONLY) | C40: =SUM('PM ONLY'!Q2:Q2000) -> 2540
B41: Ancillary Income — Parking (PM ONLY) | C41: =SUM('PM ONLY'!R2:R2000) -> 1180
B42: Ancillary Income — Storage (PM ONLY) | C42: =SUM('PM ONLY'!S2:S2000) -> 50
B44: 3. Leasing Pipeline
...

Sheet PM ONLY
A1: Management Agreement Date | B1: Service Type | C1: Owner | D1: Property | E1: Unit # | F1: Assigned PM | G1: Assigned Leasing Agent | H1: Occupancy Status | I1: Service Status | J1: Tenant Name | K1: Email | L1: Phone Number | M1: Lease Move In | N1: Lease Move out | O1: Leasing Fee | P1: Rent | Q1: Pet Fee | R1: Parking | S1: Storage | T1: Management Fee % | U1: Management Fee | V1: TOTAL FEES WITH GST | W1: Total Owner Income | X1: Total Owner disbursement | Y1: Notes
A2: 46115 | B2: Property Management | C2: 2327327 Ontario Inc | D2: 12115 93 Street Northwest, Edmonton, AB T5G 1E9 | E2: MAIN | F2: Thomas Bruchig | H2: Vacant | I2: Active | O2: 599 | T2: 0.05 | U2: =P2*T2 -> 0 | W2: =P2+Q2+R2+S2 -> 0 | X2: =SUM(P2:S2)-U2 -> 0
A3: 46115 | B3: Property Management | C3: 2327327 Ontario Inc | D3: 12115 93 Street Northwest, Edmonton, AB T5G 1E9 | E3: LOWER | F3: Thomas Bruchig | H3: Vacant | I3: Active | O3: 599 | T3: 0.05 | U3: =P3*T3 -> 0 | W3: =P3+Q3+R3+S3 -> 0 | X3: =SUM(P3:S3)-U3 -> 0
A4: 46115 | B4: Property Management | C4: 2327327 Ontario Inc | D4: 12115 93 Street Northwest, Edmonton, AB T5G 1E9 | E4: GARAGE | F4: Thomas Bruchig | H4: Vacant | I4: Active | O4: 599 | T4: 0.05 | U4: =P4*T4 -> 0 | W4: =P4+Q4+R4+S4 -> 0 | X4: =SUM(P4:S4)-U4 -> 0
A5: 46115 | B5: Property Management | C5: 2327327 Ontario Inc | D5: 12117 93 Street Northwest, Edmonton, AB T5G 1E9 | E5: MAIN | F5: Thomas Bruchig | H5: Vacant | I5: Active | O5: 599 | T5: 0.05 | U5: =P5*T5 -> 0 | W5: =P5+Q5+R5+S5 -> 0 | X5: =SUM(P5:S5)-U5 -> 0
A6: 46115 | B6: Property Management | C6: 2327327 Ontario Inc | D6: 12117 93 Street Northwest, Edmonton, AB T5G 1E9 | E6: LOWER | F6: Thomas Bruchig | H6: Vacant | I6: Active | O6: 599 | T6: 0.05 | U6: =P6*T6 -> 0 | W6: =P6+Q6+R6+S6 -> 0 | X6: =SUM(P6:S6)-U6 -> 0
A7: 46115 | B7: Property Management | C7: 2327327 Ontario Inc | D7: 12117 93 Street Northwest, Edmonton, AB T5G 1E9 | E7: GARAGE | F7: Thomas Bruchig | H7: Vacant | I7: Active | O7: 599 | T7: 0.05 | U7: =P7*T7 -> 0 | W7: =P7+Q7+R7+S7 -> 0 | X7: =SUM(P7:S7)-U7 -> 0
A8: 46178 | B8: Property Management | C8: 2690036 Alberta Ltd. | D8: 12021 95A Street Northwest, Edmonton, AB T5G 1R6 | E8: MAIN | F8: Thomas Bruchig | H8: Occupied | I8: Active | J8: Chad Conlon Dean Mills | K8: chadconlon.yukon@gmail.com | L8: (867) 333-3629 | M8: 46218 | N8: 46582 | O8: 599 | P8: 1950 | T8: 0.05 | U8: =P8*T8 -> 97.5 | V8: =SUM(U8,(U8*0.05)) -> 102.375 | W8: =P8+Q8+R8+S8 -> 1950 | X8: =SUM(P8:S8)-V8 -> 1847.625
A9: 46178 | B9: Property Management | C9: 2690036 Alberta Ltd. | D9: 12021 95A Street Northwest, Edmonton, AB T5G 1R6 | E9: LOWER | F9: Thomas Bruchig | H9: Vacant | I9: Active | O9: 599 | T9: 0.05 | U9: =P9*T9 -> 0 | W9: =P9+Q9+R9+S9 -> 0 | X9: =SUM(P9:S9)-U9 -> 0
A10: 46178 | B10: Property Management | C10: 2690036 Alberta Ltd. | D10: 12021 95A Street Northwest, Edmonton, AB T5G 1R6 | E10: GARDEN | F10: Thomas Bruchig | H10: Vacant | I10: Active | O10: 599 | T10: 0.05 | U10: =P10*T10 -> 0 | W10: =P10+Q10+R10+S10 -> 0 | X10: =SUM(P10:S10)-U10 -> 0
A11: 46023 | B11: Property Management | C11: 2700655 Alberta Ltd. | D11: 8-PLEX BANFF TRAIL Property, 2439 26 Avenue Northwest, Calgary, AB T2M 2H1 | E11: 2439-26A | F11: Junny Ko | H11: Occupied | I11: Active | J11: Seath, Anne Elizabeth | K11: aeseath@gmail.com | L11: (587) 938 - 6929 | M11: 46054 | N11: 46507 | O11: 799 | P11: 2475 | Q11: 50 | T11: 0.05 | U11: =P11*T11 -> 123.75 | V11: =SUM(U11,(U11*0.05)) -> 129.9375 | W11: =P11+Q11+R11+S11 -> 2525 | X11: =SUM(P11:S11)-V11 -> 2395.0625
A12: 46023 | B12: Property Management | C12: 2700655 Alberta Ltd. | D12: 8-PLEX BANFF TRAIL Property, 2439 26 Avenue Northwest, Calgary, AB T2M 2H1 | E12: 2439R-26 | F12: Junny Ko | H12: Occupied | I12: Active | J12: Robinson, Logan | K12: Loganjcrobinson@gmail.com | L12: (905) 716 - 9968 | M12: 46011 | N12: 46477 | O12: 799 | P12: 1300 | Q12: 50 | T12: 0.05 | U12: =P12*T12 -> 65 | V12: =SUM(U12,(U12*0.05)) -> 68.25 | W12: =P12+Q12+R12+S12 -> 1350 | X12: =SUM(P12:S12)-V12 -> 1281.75
A13: 46023 | B13: Property Management | C13: 2700655 Alberta Ltd. | D13: 8-PLEX BANFF TRAIL Property, 2439 26 Avenue Northwest, Calgary, AB T2M 2H1 | E13: 2616-24S | F13: Junny Ko | H13: Occupied | I13: Active | J13: Loader, Lewis MacDonald, Kaitlyn | K13: loader.lewis@gmail.com Kaitlyn.a.macdonald@shaw.ca | L13: (709) 743 - 9428 | M13: 46143 | N13: 46507 | O13: 799 | P13: 2200 | Q13: 75 | R13: 100 | T13: 0.05 | U13: =P13*T13 -> 110 | V13: =SUM(U13,(U13*0.05)) -> 115.5 | W13: =P13+Q13+R13+S13 -> 2375 | X13: =SUM(P13:S13)-V13 -> 2259.5
A14: 46023 | B14: Property Management | C14: 2700655 Alberta Ltd. | D14: 8-PLEX BANFF TRAIL Property, 2439 26 Avenue Northwest, Calgary, AB T2M 2H1 | E14: 2616R-24 | F14: Junny Ko | H14: Occupied | I14: Active | J14: Savoie, Bjorn | K14: bjornsavoie@gmail.com | L14: (403) 923 - 2384 | M14: 46012 | N14: 46477 | O14: 799 | P14: 1300 | T14: 0.05 | U14: =P14*T14 -> 65 | V14: =SUM(U14,(U14*0.05)) -> 68.25 | W14: =P14+Q14+R14+S14 -> 1300 | X14: =SUM(P14:S14)-V14 -> 1231.75
A15: 46023 | B15: Property Management | C15: 2700655 Alberta Ltd. | D15: 8-PLEX BANFF TRAIL Property, 2439 26 Avenue Northwest, Calgary, AB T2M 2H1 | E15: 2618-24S | F15: Junny Ko | H15: Occupied | I15: Active | J15: Lalanne, Gabrielle | K15: Gabriellelalanne@hotmail.com | L15: (438) 451 - 7676 | M15: 46082 | N15: 46538 | O15: 799 | P15: 2300 | Q15: 25 | R15: 100 | T15: 0.05 | U15: =P15*T15 -> 115 | V15: =SUM(U15,(U15*0.05)) -> 120.75 | W15: =P15+Q15+R15+S15 -> 2425 | X15: =SUM(P15:S15)-V15 -> 2304.25
A16: 46023 | B16: Property Management | C16: 2700655 Alberta Ltd. | D16: 8-PLEX BANFF TRAIL Property, 2439 26 Avenue Northwest, Calgary, AB T2M 2H1 | E16: 2618R-24 | F16: Junny Ko | H16: Occupied | I16: Active | J16: Olaniran, Ameera Folashade | K16: olaniran587@gmail.com | L16: (403) 506 - 1601 | M16: 45992 | N16: 46446 | O16: 799 | P16: 1350 | T16: 0.05 | U16: =P16*T16 -> 67.5 | V16: =SUM(U16,(U16*0.05)) -> 70.875 | W16: =P16+Q16+R16+S16 -> 1350 | X16: =SUM(P16:S16)-V16 -> 1279.125
A17: 46023 | B17: Property Management | C17: 2700655 Alberta Ltd. | D17: 8-PLEX BANFF TRAIL Property, 2439 26 Avenue Northwest, Calgary, AB T2M 2H1 | E17: 2620-24S | F17: Junny Ko | H17: Occupied | I17: Active | J17: Aragao Barros, Mariah Bakir, Noor | K17: mariaharagao90@gmail.com noorbakir@gmail.com | L17: (587) 917 - 8775 (587) 917 - 6699 | M17: 46143 | N17: 46507 | O17: 799 | P17: 2200 | R17: 100 | T17: 0.05 | U17: =P17*T17 -> 110 | V17: =SUM(U17,(U17*0.05)) -> 115.5 | W17: =P17+Q17+R17+S17 -> 2300 | X17: =SUM(P17:S17)-V17 -> 2184.5
A18: 46023 | B18: Property Management | C18: 2700655 Alberta Ltd. | D18: 8-PLEX BANFF TRAIL Property, 2439 26 Avenue Northwest, Calgary, AB T2M 2H1 | E18: 2620R-24 | F18: Junny Ko | H18: Occupied | I18: Active | J18: Steel, Adison | K18: adisonsteel16@icloud.com | L18: (250) 908 - 7779 | M18: 46143 | N18: 46507 | O18: 799 | P18: 1100 | S18: 50 | T18: 0.05 | U18: =P18*T18 -> 55 | V18: =SUM(U18,(U18*0.05)) -> 57.75 | W18: =P18+Q18+R18+S18 -> 1150 | X18: =SUM(P18:S18)-V18 -> 1092.25
A19: 46045 | B19: Property Management | C19: 2758231 Alberta Inc. | D19: 515 Black Stone BLVD | E19: UPPER | F19: Thomas Bruchig | H19: Occupied | I19: Active | J19: Kolton Redekop April Woodhouse | K19: koltonredekop@gmail.com aprilwest22@gmail.com | L19: (250) 826-2699 (250) 826-8318 | M19: 46143 | N19: 46507 | O19: 250 | P19: 1950 | Q19: 75 | T19: 0.05 | U19: =P19*T19 -> 97.5 | V19: =SUM(U19,(U19*0.05)) -> 102.375 | W19: =P19+Q19+R19+S19 -> 2025 | X19: =SUM(P19:S19)-V19 -> 1922.625
A20: 46045 | B20: Property Management | C20: 2758231 Alberta Inc. | D20: 515 Black Stone BLVD | E20: LOWER | F20: Thomas Bruchig | H20: Vacant | I20: Active | O20: 250 | T20: 0.05 | U20: =P20*T20 -> 0 | W20: =P20+Q20+R20+S20 -> 0 | X20: =SUM(P20:S20)-U20 -> 0
A21: 46045 | B21: Property Management | C21: 2758231 Alberta Inc. | D21: 517 Black Stone Boulevard | E21: UPPER | F21: Thomas Bruchig | H21: Occupied | I21: Active | J21: Terrell Rankin | K21: Terrellrankin900@gmail.com | L21: (780) 238-1793 | M21: 46204 | N21: 46568 | O21: 250 | P21: 1950 | Q21: 50 | T21: 0.05 | U21: =P21*T21 -> 97.5 | V21: =SUM(U21,(U21*0.05)) -> 102.375 | W21: =P21+Q21+R21+S21 -> 2000 | X21: =SUM(P21:S21)-V21 -> 1897.625
A22: 46045 | B22: Property Management | C22: 2758231 Alberta Inc. | D22: 517 Black Stone Boulevard | E22: LOWER | F22: Thomas Bruchig | H22: Occupied | I22: Active | J22: Emily Kellett | K22: emilykellett56@gmail.com | L22: (780) 226-7446 | M22: 46174 | N22: 46538 | O22: 250 | P22: 950 | Q22: 25 | T22: 0.05 | U22: =P22*T22 -> 47.5 | V22: =SUM(U22,(U22*0.05)) -> 49.875 | W22: =P22+Q22+R22+S22 -> 975 | X22: =SUM(P22:S22)-V22 -> 925.125
A23: 46045 | B23: Property Management | C23: 2758231 Alberta Inc. | D23: 519 Black Stone BLVD | E23: UPPER | F23: Thomas Bruchig | H23: Occupied | I23: Active | J23: Danielle Brooking Tylor Watson | K23: daniellebrooking@gmail.com twatson16@icloud.com | L23: (780) 312-4993 | M23: 46143 | N23: 46507 | O23: 250 | P23: 1950 | Q23: 25 | T23: 0.05 | U23: =P23*T23 -> 97.5 | V23: =SUM(U23,(U23*0.05)) -> 102.375 | W23: =P23+Q23+R23+S23 -> 1975 | X23: =SUM(P23:S23)-V23 -> 1872.625
A24: 46045 | B24: Property Management | C24: 2758231 Alberta Inc. | D24: 519 Black Stone BLVD | E24: LOWER | F24: Thomas Bruchig | H24: Occupied | I24: Active | J24: Max Austman | K24: max.austman@gmail.com | L24: (780) 225-1319 | M24: 46204 | N24: 46568 | O24: 250 | P24: 950 | Q24: 25 | T24: 0.05 | U24: =P24*T24 -> 47.5 | V24: =SUM(U24,(U24*0.05)) -> 49.875 | W24: =P24+Q24+R24+S24 -> 975 | X24: =SUM(P24:S24)-V24 -> 925.125
A25: 46045 | B25: Property Management | C25: 2758231 Alberta Inc. | D25: 521 Black Stone BLVD | E25: UPPER | F25: Thomas Bruchig | H25: Occupied | I25: Active | J25: Chelsey Tychowsky Austin Young | K25: chelsey.tychkowsky@gmail.com austin_jyoung@outlook.com | L25: (780) 239-5665 (587) 937-4130 | M25: 46174 | N25: 46538 | O25: 250 | P25: 1950 | Q25: 50 | T25: 0.05 | U25: =P25*T25 -> 97.5 | V25: =SUM(U25,(U25*0.05)) -> 102.375 | W25: =P25+Q25+R25+S25 -> 2000 | X25: =SUM(P25:S25)-V25 -> 1897.625
A26: 46045 | B26: Property Management | C26: 2758231 Alberta Inc. | D26: 521 Black Stone BLVD | E26: LOWER | F26: Thomas Bruchig | H26: Occupied | I26: Active | J26: Nathan Theriault | K26: josephm4347@gmail.com | M26: 46143 | N26: 46507 | O26: 250 | P26: 950 | T26: 0.05 | U26: =P26*T26 -> 47.5 | V26: =SUM(U26,(U26*0.05)) -> 49.875 | W26: =P26+Q26+R26+S26 -> 950 | X26: =SUM(P26:S26)-V26 -> 900.125
A27: 46045 | B27: Property Management | C27: 2758231 Alberta Inc. | D27: 523 Black Stone BLVD | E27: UPPER | F27: Thomas Bruchig | H27: Occupied | I27: Active | J27: Jayna May Kayden Ewen | K27: jayna2258@gmail.com Kaydenewenmjk@gmail.com | L27: (780) 901-6381 (403) 373-7530 | M27: 46143 | N27: 46507 | O27: 250 | P27: 1950 | Q27: 50 | T27: 0.05 | U27: =P27*T27 -> 97.5 | V27: =SUM(U27,(U27*0.05)) -> 102.375 | W27: =P27+Q27+R27+S27 -> 2000 | X27: =SUM(P27:S27)-V27 -> 1897.625
A28: 46045 | B28: Property Management | C28: 2758231 Alberta Inc. | D28: 523 Black Stone BLVD | E28: LOWER | F28: Thomas Bruchig | H28: Vacant | I28: Active | O28: 250 | T28: 0.05 | U28: =P28*T28 -> 0 | W28: =P28+Q28+R28+S28 -> 0 | X28: =SUM(P28:S28)-U28 -> 0
A29: 46045 | B29: Property Management | C29: 2758231 Alberta Inc. | D29: 525 Black Stone BLVD | E29: UPPER | F29: Thomas Bruchig | H29: Occupied | I29: Active | J29: Leonard Flinn Andrew Wright Kristin Flinn | K29: len_flinn@yahoo.com wreckitwright@gmail.com | L29: (403) 872-1182 (587) 591-3591 | M29: 46143 | N29: 46507 | O29: 250 | P29: 1950 | T29: 0.05 | U29: =P29*T29 -> 97.5 | V29: =SUM(U29,(U29*0.05)) -> 102.375 | W29: =P29+Q29+R29+S29 -> 1950 | X29: =SUM(P29:S29)-V29 -> 1847.625
A30: 46045 | B30: Property Management | C30: 2758231 Alberta Inc. | D30: 525 Black Stone BLVD | E30: LOWER | F30: Thomas Bruchig | H30: Occupied | I30: Active | J30: Sumandeep Kaur Deepinder Sidhu | K30: ksumandeepg@gmail.com sidhudeepinder47@gmail.com | M30: 46174 | N30: 46538 | O30: 250 | P30: 950 | T30: 0.05 | U30: =P30*T30 -> 47.5 | V30: =SUM(U30,(U30*0.05)) -> 49.875 | W30: =P30+Q30+R30+S30 -> 950 | X30: =SUM(P30:S30)-V30 -> 900.125
A31: 46045 | B31: Property Management | C31: 2758231 Alberta Inc. | D31: 527 Black Stone Boulevard | E31: UPPER | F31: Thomas Bruchig | H31: Occupied | I31: Active | J31: Jay Emms | K31: jemms@primemoversinc.ca | L31: (403) 526-8757 | M31: 46143 | N31: 46507 | O31: 250 | P31: 1950 | T31: 0.05 | U31: =P31*T31 -> 97.5 | V31: =SUM(U31,(U31*0.05)) -> 102.375 | W31: =P31+Q31+R31+S31 -> 1950 | X31: =SUM(P31:S31)-V31 -> 1847.625
A32: 46045 | B32: Property Management | C32: 2758231 Alberta Inc. | D32: 527 Black Stone Boulevard | E32: LOWER | F32: Thomas Bruchig | H32: Occupied | I32: Active | J32: Emily Greenwood | K32: emilygreenwood01@gmail.com | L32: (587) 337-8864 | M32: 46143 | N32: 46507 | O32: 250 | P32: 950 | Q32: 25 | T32: 0.05 | U32: =P32*T32 -> 47.5 | V32: =SUM(U32,(U32*0.05)) -> 49.875 | W32: =P32+Q32+R32+S32 -> 975 | X32: =SUM(P32:S32)-V32 -> 925.125
A33: 46045 | B33: Property Management | C33: 2758231 Alberta Inc. | D33: 529 Black Stone BLVD | E33: UPPER | F33: Thomas Bruchig | H33: Occupied | I33: Active | J33: Kennedy Anshelm | K33: k.faye.98@gmail.com | L33: (780) 217-7724 | M33: 46174 | N33: 46538 | O33: 250 | P33: 1950 | Q33: 50 | T33: 0.05 | U33: =P33*T33 -> 97.5 | V33: =SUM(U33,(U33*0.05)) -> 102.375 | W33: =P33+Q33+R33+S33 -> 2000 | X33: =SUM(P33:S33)-V33 -> 1897.625
A34: 46045 | B34: Property Management | C34: 2758231 Alberta Inc. | D34: 529 Black Stone BLVD | E34: LOWER | F34: Thomas Bruchig | H34: Occupied | I34: Active | J34: Autumn Flanagan | K34: autumnflanagan12@gmail.com | L34: (403) 848-4566 | M34: 46174 | N34: 46538 | O34: 250 | P34: 950 | T34: 0.05 | U34: =P34*T34 -> 47.5 | V34: =SUM(U34,(U34*0.05)) -> 49.875 | W34: =P34+Q34+R34+S34 -> 950 | X34: =SUM(P34:S34)-V34 -> 900.125
A35: 46045 | B35: Property Management | C35: 2758231 Alberta Inc. | D35: 531 Black Stone BLVD | E35: UPPER | F35: Thomas Bruchig | H35: Occupied | I35: Active | J35: Amanda Fakkeldy Roland Doherty | K35: amandafakkeldy@gmail.com rollietheminer@gmail.com | L35: (825) 556-6767 | M35: 46143 | N35: 46507 | O35: 250 | P35: 1950 | Q35: 50 | T35: 0.05 | U35: =P35*T35 -> 97.5 | V35: =SUM(U35,(U35*0.05)) -> 102.375 | W35: =P35+Q35+R35+S35 -> 2000 | X35: =SUM(P35:S35)-V35 -> 1897.625
A36: 46045 | B36: Property Management | C36: 2758231 Alberta Inc. | D36: 531 Black Stone BLVD | E36: LOWER | F36: Thomas Bruchig | H36: Occupied | I36: Active | J36: Ian Vanwoudenberg Alysha Amber | K36: ianvan2486@gmail.com alyshaambler@gmail.com | L36: (780) 504-4375 (780) 385-1454 | M36: 46174 | N36: 46538 | O36: 250 | P36: 950 | Q36: 50 | T36: 0.05 | U36: =P36*T36 -> 47.5 | V36: =SUM(U36,(U36*0.05)) -> 49.875 | W36: =P36+Q36+R36+S36 -> 1000 | X36: =SUM(P36:S36)-V36 -> 950.125
A37: 46045 | B37: Property Management | C37: 2758231 Alberta Inc. | D37: 533 Blackstone BLVD | E37: UPPER | F37: Thomas Bruchig | H37: Occupied | I37: Active | J37: Cheri Davis Sheldon MacDonald | K37: cheri.lynne.davis@outlook.com HAIEMMJVRLAMANG@GMAIL.COM | L37: (587) 937-1820 (587) 586-1141 | M37: 46143 | N37: 46507 | O37: 250 | P37: 1950 | Q37: 75 | T37: 0.05 | U37: =P37*T37 -> 97.5 | V37: =SUM(U37,(U37*0.05)) -> 102.375 | W37: =P37+Q37+R37+S37 -> 2025 | X37: =SUM(P37:S37)-V37 -> 1922.625
A38: 46045 | B38: Property Management | C38: 2758231 Alberta Inc. | D38: 533 Blackstone BLVD | E38: LOWER | F38: Thomas Bruchig | H38: Vacant | I38: Active | O38: 250 | T38: 0.05 | U38: =P38*T38 -> 0 | W38: =P38+Q38+R38+S38 -> 0 | X38: =SUM(P38:S38)-U38 -> 0
A39: 46045 | B39: Property Management | C39: 2758231 Alberta Inc. | D39: 537 Black Stone BLVD | E39: UPPER | F39: Thomas Bruchig | H39: Occupied | I39: Active | J39: Breeanna Blakeburn Jesse Webb | K39: blakeburnwebb@gmail.com Jessewebb718@gmail.com | L39: (780) 335-5554 (780) 360-9988 | M39: 46143 | N39: 46507 | O39: 250 | P39: 1950 | Q39: 50 | T39: 0.05 | U39: =P39*T39 -> 97.5 | V39: =SUM(U39,(U39*0.05)) -> 102.375 | W39: =P39+Q39+R39+S39 -> 2000 | X39: =SUM(P39:S39)-V39 -> 1897.625
A40: 46045 | B40: Property Management | C40: 2758231 Alberta Inc. | D40: 537 Black Stone BLVD | E40: LOWER | F40: Thomas Bruchig | H40: Occupied | I40: Active | J40: Octavia Johnson Maciej Adamski | K40: joctavia736@gmail.com maciejadamski@gmail.com | L40: (780) 216-2423 (431) 277-9510 | M40: 46143 | N40: 46507 | O40: 250 | P40: 950 | Q40: 25 | T40: 0.05 | U40: =P40*T40 -> 47.5 | V40: =SUM(U40,(U40*0.05)) -> 49.875 | W40: =P40+Q40+R40+S40 -> 975 | X40: =SUM(P40:S40)-V40 -> 925.125
...

Sheet LEASE ONLY
A1: Management Agreement Date | B1: Service Type | C1: Owner | D1: Property | E1: Assigned PM | F1: Unit # | G1: Assigned Leasing Agent | H1: Occupancy Status | I1: Service Status | J1: Lease Move In | K1: Lease Move out | L1: Leasing Fee | M1: Rent | N1: Pet Fee | O1: Parking | P1: Storage | Q1: Leasing Fee with GST | R1: Total Owner Income | S1: Total Owner disbursement | T1: ADMIN Notes | U1: ACCOUNTING NOTES- INDICATE IF IT FILES ARE DONE AND CLOSED
A2: 46185 | B2: Lease Only | C2: Shahab Wasely | D2: 8 SOUTHWINDS COMMON SW, AIRDRIE AB T4B 5T9 | E2: Junny Ko | F2: BSMT | G2: Kay Villocillo | H2: Vacant | I2: Active | J2: 46249 | K2: 46630 | L2: 599 | M2: 1250 | N2: 0 | O2: 0 | P2: 0 | Q2: =SUM(L2,(L2*0.05)) -> 628.95 | R2: =M2+N2+O2+P2 -> 1250 | S2: =SUM(M2:P2)-Q2 -> 621.05
A3: 46183 | B3: Lease Only | C3: Ravinder Sahota | D3: 3931 62 St NW, Calgary, AB, T3B 6R1 (New Bowness) | E3: Junny Ko | G3: Lorenzo Cabason, Hermant Persaud | H3: Vacant | I3: Active | L3: 799 | M3: 2550 | Q3: =SUM(L3,(L3*0.05)) -> 838.95 | R3: =M3+N3+O3+P3 -> 2550 | S3: =SUM(M3:P3)-Q3 -> 1711.05
A4: 46162 | B4: Lease Only | C4: Oluwabukunola Farayola | D4: 19652 SHERIFF KING ST SW, CALGARY AB T2X 5T9 | G4: Parmeet Singh | H4: Occupied | I4: Active | L4: 1200 | Q4: =SUM(L4,(L4*0.05)) -> 1260 | R4: =M4+N4+O4+P4 -> 0 | S4: =SUM(M4:P4)-Q4 -> -1260
A5: 46140 | B5: Lease Only | C5: Keethana Chandrakuma | D5: 2039 Saddleback Rd NW, Edmonton, AB T6J 4T4 | G5: Thomas Bruchig | L5: 699 | Q5: =SUM(L5,(L5*0.05)) -> 733.95 | R5: =M5+N5+O5+P5 -> 0 | S5: =SUM(M5:P5)-Q5 -> -733.95
A6: 46128 | B6: Lease Only | C6: Patric Stettler | D6: 227 7 ST NE, CALGARY AB T2E 4C1 | E6: Junny Ko | F6: 102 | G6: Junny Ko | L6: 799 | Q6: =SUM(L6,(L6*0.05)) -> 838.95 | R6: =M6+N6+O6+P6 -> 0 | S6: =SUM(M6:P6)-Q6 -> -838.95
A7: 46086 | B7: Lease Only | C7: Salvador Carlos Hernandez Ramirez | D7: A-934 5A ST NW, CALGARY AB T2N 1R6 | G7: Carla Barney | I7: Terminated | L7: 599 | Q7: =SUM(L7,(L7*0.05)) -> 628.95 | R7: =M7+N7+O7+P7 -> 0 | S7: =SUM(M7:P7)-Q7 -> -628.95
A8: 46072 | B8: Lease Only | C8: Salvador Carlos Hernandez Ramirez | D8: 203-1027 CAMERON AVE SW, CALGARY AB T2T 0K3 | G8: Carla Barney | H8: Occupied | I8: Active | L8: 999 | Q8: =SUM(L8,(L8*0.05)) -> 1048.95 | R8: =M8+N8+O8+P8 -> 0 | S8: =SUM(M8:P8)-Q8 -> -1048.95
A9: February 19, 0206 | B9: Lease Only | C9: Tamar Kathy Konevski | D9: 2114 - 63 Corner Glen Crescent Northeast | E9: Junny Ko | F9: SFH | G9: Kay Villocillo | H9: Occupied | I9: Active | L9: 799 | M9: 1680 | N9: 100 | Q9: =SUM(L9,(L9*0.05)) -> 838.95 | R9: =M9+N9+O9+P9 -> 1780 | S9: =SUM(M9:P9)-Q9 -> 941.05 | T9: WE DON'T MANAGE THIS TENANT, PAD FORM Service only
A10: 46071 | B10: Lease Only | C10: Kofi Poku Acheampong | D10: 603 ORCHARDS BLVD SW, EDMONTON AB T6X 2W8 | E10: Thomas Bruchig | G10: Thomas Bruchig | L10: 500 | Q10: =SUM(L10,(L10*0.05)) -> 525 | R10: =M10+N10+O10+P10 -> 0 | S10: =SUM(M10:P10)-Q10 -> -525
A11: 46046 | B11: Lease Only | C11: Salvador Carlos Hernandez Ramirez | D11: 1920 31 ST SW, CALGARY AB T3E 2M9 | F11: 2 | G11: Carla Barney | L11: 599 | Q11: =SUM(L11,(L11*0.05)) -> 628.95 | R11: =M11+N11+O11+P11 -> 0 | S11: =SUM(M11:P11)-Q11 -> -628.95
A12: 46035 | B12: Lease Only | C12: Ankit Kainth | D12: 230 Dawson Way, Chestermere, AB T1X 2R5 | G12: Parmeet Singh | L12: 400 | Q12: =SUM(L12,(L12*0.05)) -> 420 | R12: =M12+N12+O12+P12 -> 0 | S12: =SUM(M12:P12)-Q12 -> -420
A13: 46031 | B13: Lease Only | C13: Karanveer Rai | D13: 6303 BOW CRES NW, CALGARY AB T3B 2C4 | E13: Junny Ko | G13: Kay Villocillo | I13: Terminated | L13: 799 | Q13: =SUM(L13,(L13*0.05)) -> 838.95 | R13: =M13+N13+O13+P13 -> 0 | S13: =SUM(M13:P13)-Q13 -> -838.95
A14: 46003 | B14: Lease Only | C14: Victor Ifaturoti | D14: 87 HUXLAND RD NE, CALGARY AB T2A 6Z7 | E14: Junny Ko | G14: Junny Ko | L14: 699 | Q14: =SUM(L14,(L14*0.05)) -> 733.95 | R14: =M14+N14+O14+P14 -> 0 | S14: =SUM(M14:P14)-Q14 -> -733.95
A15: 45998 | B15: Lease Only | C15: Bharat Kumar Rajput | D15: 9798 Hidden Valley Dr NW, Calgary, AB T3A 5L2 | G15: Parmeet Singh | L15: 799 | Q15: =SUM(L15,(L15*0.05)) -> 838.95 | R15: =M15+N15+O15+P15 -> 0 | S15: =SUM(M15:P15)-Q15 -> -838.95
A16: 45995 | B16: Lease Only | C16: Amarjit Singh | D16: 247 Redstone Blvd NE, Calgary, AB T3N 1B6 | E16: Junny Ko | G16: Kay Villocillo | I16: Terminated | L16: 599 | Q16: =SUM(L16,(L16*0.05)) -> 628.95 | R16: =M16+N16+O16+P16 -> 0 | S16: =SUM(M16:P16)-Q16 -> -628.95
A17: 45994 | B17: Lease Only | C17: Gurpreet Dhillon | D17: 139 Lewiston Drive NE, Calgary, Alberta | G17: Parmeet Singh | L17: 500 | Q17: =SUM(L17,(L17*0.05)) -> 525 | R17: =M17+N17+O17+P17 -> 0 | S17: =SUM(M17:P17)-Q17 -> -525
C18: Nwando Chineze Ezeagwula | D18: 178 DRYSTONE WAY NW CALGARY AB T3R 2M1 | E18: Junny Ko | H18: Vacant | I18: Active | L18: 799

Sheet TENANTS
A1: Property | B1: Tenant Name | C1: Notes
A2: 63 Corner Glen Crois. NE 501 | B2: Habibullah Nazari | C2: security deposit
A3: 508-836 15 Ave SW, Unit | B3: Anastassia Krioutchkova
A4: 202R 1408 Renfrew Drive NE Calgary | B4: Liam Wong
A5: 76 Hidden Point Northwest | B5: Ines Alonso de Vega
A6: 232 Ricardo Ranch Avenue Southeast | B6: Olasanmi Uthman Adeyiga
A7: 236 Ricardo Ranch Avenue Southeast | B7: Myles Fogarty
A8: 236 Ricardo Ranch Avenue Southeast | B8: Grace Fogarty
A9: 8-PLEX BANFF TRAIL Property, Unit 2620R-24 | B9: Adison Steel
B10: Douglas steel
A11: 133 Pantego Road Northwest | B11: Heather Aleinik
B12: Jesse Dickie
A13: 7835 Fairmount Drive Southeast | B13: Mohammad Saleem
B14: Maria Naikpai
A15: 1408 Renfrew Drive NE | B15: Sindy Flores
B16: Deborah Chavez
A17: 4347 Seton Drive SE | B17: Chad Heaslip
B18: Oneil Kaylynn
A19: 1408 Renfrew Drive NE | B19: Vinze Torres
B20: Kiara Opperman
B21: Madison Norris
B22: Jordyn.
A23: 8149-111 St. NW Edmonton | B23: Basam Ahmad
B24: Frank Wang
A25: 18904 - 86A Ave | B25: Nicole Hrynyk
A26: 11404 42 St. Edmonton | B26: Jordan Lemoine
B27: Hannah Weymouth
A28: 309 1031 173 St Edmonton | B28: Madisen Hutchinson
B29: Jase Enyedy

Sheet Lease Move Out Search
A1: Enter the lease move out date range below. | D1: Address | E1: City | F1: Unit / Type | G1: Tenant Name | H1: Phone | I1: Email | J1: Lease Move In | K1: Lease Move out
D2: =IFERROR(__xludf.dummyfunction("LET(sd,$A$4,ed,$A$7,IF(OR(sd="""",ed=""""),""Enter a Start Date and End Date to view lease move-outs."",IF(sd>ed,""Start Date cannot be later than End Date."",IFERROR(SORT(FILTER(HSTACK('PM ONLY'!D2:D2025,IF('PM ONLY'!D2:D2025<>"""","""",""""),'PM ONLY'!E"&"2:E2025,'PM ONLY'!J2:J2025,'PM ONLY'!L2:L2025,'PM ONLY'!K2:K2025,'PM ONLY'!M2:M2025,'PM ONLY'!N2:N2025),ISNUMBER('PM ONLY'!N2:N2025),'PM ONLY'!N2:N2025>=sd,'PM ONLY'!N2:N2025<=ed),8,TRUE,1,TRUE,3,TRUE,4,TRUE),""No lease move-outs found for this date range"&".""))))"),"406-626 14 Avenue Southwest, Calgary, AB, T2R 0X4") -> 406-626 14 Avenue Southwest, Calgary, AB, T2R 0X4 | E2: =IFERROR(__xludf.dummyfunction("""COMPUTED_VALUE"""),"") | F2: =IFERROR(__xludf.dummyfunction("""COMPUTED_VALUE"""),"SFH") -> SFH | G2: =IFERROR(__xludf.dummyfunction("""COMPUTED_VALUE"""),"Swain, Daisy") -> Swain, Daisy | H2: =IFERROR(__xludf.dummyfunction("""COMPUTED_VALUE"""),"(403) 554 - 5130") -> (403) 554 - 5130 | I2: =IFERROR(__xludf.dummyfunction("""COMPUTED_VALUE"""),"daisyswain@live.com") -> daisyswain@live.com | J2: =IFERROR(__xludf.dummyfunction("""COMPUTED_VALUE"""),45717) -> 45717 | K2: =IFERROR(__xludf.dummyfunction("""COMPUTED_VALUE"""),46203) -> 46203
A3: START DATE | D3: =IFERROR(__xludf.dummyfunction("""COMPUTED_VALUE"""),"1936 35 Street Southwest") -> 1936 35 Street Southwest | E3: =IFERROR(__xludf.dummyfunction("""COMPUTED_VALUE"""),"") | F3: =IFERROR(__xludf.dummyfunction("""COMPUTED_VALUE"""),2) -> 2 | G3: =IFERROR(__xludf.dummyfunction("""COMPUTED_VALUE"""),"Carla Sofia Lena Unger") -> Carla Sofia Lena Unger | J3: =IFERROR(__xludf.dummyfunction("""COMPUTED_VALUE"""),45900) -> 45900 | K3: =IFERROR(__xludf.dummyfunction("""COMPUTED_VALUE"""),46234) -> 46234
A4: 46174 | D4: =IFERROR(__xludf.dummyfunction("""COMPUTED_VALUE"""),"1936 35 Street Southwest") -> 1936 35 Street Southwest | E4: =IFERROR(__xludf.dummyfunction("""COMPUTED_VALUE"""),"") | F4: =IFERROR(__xludf.dummyfunction("""COMPUTED_VALUE"""),"4B") -> 4B | G4: =IFERROR(__xludf.dummyfunction("""COMPUTED_VALUE"""),"Adriana Bouma-Yeme") -> Adriana Bouma-Yeme | J4: =IFERROR(__xludf.dummyfunction("""COMPUTED_VALUE"""),45870) -> 45870 | K4: =IFERROR(__xludf.dummyfunction("""COMPUTED_VALUE"""),46234) -> 46234
D5: =IFERROR(__xludf.dummyfunction("""COMPUTED_VALUE"""),"96 Arbour Crest Dr NW") -> 96 Arbour Crest Dr NW | E5: =IFERROR(__xludf.dummyfunction("""COMPUTED_VALUE"""),"") | F5: =IFERROR(__xludf.dummyfunction("""COMPUTED_VALUE"""),"LOWER") -> LOWER | G5: =IFERROR(__xludf.dummyfunction("""COMPUTED_VALUE"""),"Razzaq, Fajad") -> Razzaq, Fajad | I5: =IFERROR(__xludf.dummyfunction("""COMPUTED_VALUE"""),"fahad.razzaq@hotmail.com") -> fahad.razzaq@hotmail.com | J5: =IFERROR(__xludf.dummyfunction("""COMPUTED_VALUE"""),45870) -> 45870 | K5: =IFERROR(__xludf.dummyfunction("""COMPUTED_VALUE"""),46234) -> 46234
A6: END DATE | D6: =IFERROR(__xludf.dummyfunction("""COMPUTED_VALUE"""),"1521 26 Avenue SW, Unit 303") -> 1521 26 Avenue SW, Unit 303 | E6: =IFERROR(__xludf.dummyfunction("""COMPUTED_VALUE"""),"") | F6: =IFERROR(__xludf.dummyfunction("""COMPUTED_VALUE"""),303) -> 303 | G6: =IFERROR(__xludf.dummyfunction("""COMPUTED_VALUE"""),"Dedek, Christopher Iftody, Lindsay") -> Dedek, Christopher Iftody, Lindsay | H6: =IFERROR(__xludf.dummyfunction("""COMPUTED_VALUE"""),"(613) 261 - 5975") -> (613) 261 - 5975 | I6: =IFERROR(__xludf.dummyfunction("""COMPUTED_VALUE"""),"cdedek@gmail.com lindsayiftody@gmail.com") -> cdedek@gmail.com lindsayiftody@gmail.com | J6: =IFERROR(__xludf.dummyfunction("""COMPUTED_VALUE"""),45901) -> 45901 | K6: =IFERROR(__xludf.dummyfunction("""COMPUTED_VALUE"""),46265) -> 46265
A7: 46265 | D7: =IFERROR(__xludf.dummyfunction("""COMPUTED_VALUE"""),"18904 86a Edmonton, AB, T5T4X8") -> 18904 86a Edmonton, AB, T5T4X8 | E7: =IFERROR(__xludf.dummyfunction("""COMPUTED_VALUE"""),"") | G7: =IFERROR(__xludf.dummyfunction("""COMPUTED_VALUE"""),"Nicole Hrynyk") -> Nicole Hrynyk | J7: =IFERROR(__xludf.dummyfunction("""COMPUTED_VALUE"""),45901) -> 45901 | K7: =IFERROR(__xludf.dummyfunction("""COMPUTED_VALUE"""),46265) -> 46265
D8: =IFERROR(__xludf.dummyfunction("""COMPUTED_VALUE"""),"236 Ricardo Ranch Avenue Southeast") -> 236 Ricardo Ranch Avenue Southeast | E8: =IFERROR(__xludf.dummyfunction("""COMPUTED_VALUE"""),"") | F8: =IFERROR(__xludf.dummyfunction("""COMPUTED_VALUE"""),"236B") -> 236B | G8: =IFERROR(__xludf.dummyfunction("""COMPUTED_VALUE"""),"Casey, Erin Nichols, Tim") -> Casey, Erin Nichols, Tim | I8: =IFERROR(__xludf.dummyfunction("""COMPUTED_VALUE"""),"tnichols@greatnorthernplumbing.com") -> tnichols@greatnorthernplumbing.com | J8: =IFERROR(__xludf.dummyfunction("""COMPUTED_VALUE"""),46082) -> 46082 | K8: =IFERROR(__xludf.dummyfunction("""COMPUTED_VALUE"""),46265) -> 46265

Sheet REALTOR FEES
A1: STATUS | B1: AKA | C1: Name | D1: Email | E1: Phone | F1: Monthly Fee | G1: Deal Fee (per transaction) | H1: Convenyancing Fee with GST Deal Fee x 1.05 | I1: Annual Cap | J1: Post-Cap Deal Fee | K1: One-time Joining Fee | L1: Learner Plan | M1: High Performer Plan | N1: Team Plan | O1: WITH PICTURE? | P1: WITH GST NUMBER? | Q1: IC AGREEMENT | R1: PAD FORM | S1: POLICY MANUAL
A2: NO LONGER AN AGENT | C2: Yen Pang | D2: yen.ableproperty@gmail.com | E2: 368-999-8098 | F2: 30 | G2: 300 | H2: =G2*1.05 -> 315 | I2: $6000/calendar year | J2: Once the annual cap is reached, the deal fee is reduced to $150.00 per transaction for the remainder of the calendar year. | O2: NO | P2: YES | Q2: YES | R2: YES | S2: YES
A3: ACTIVE AGENT | C3: Bhupinder Gill | D3: info.fyndhomes@gmail.com | E3: 403.415.4151 | F3: 30 | G3: 300 | H3: =G3*1.05 -> 315 | I3: $6000/calendar year | J3: Once the annual cap is reached, the deal fee is reduced to $150.00 per transaction for the remainder of the calendar year. | K3: $100.00 (non-refundable, due upon signing of this Agreement) | O3: YES | P3: YES | Q3: YES | R3: YES | S3: YES
A4: ACTIVE AGENT | C4: Junny Ko | D4: junny@korealty.ca | E4: (403) 400-0699 | H4: =G4*1.05 -> 0
A5: ACTIVE AGENT | B5: Sue La | C5: Ho Minh Duyen La | D5: suela.yyc@gmail.com | E5: 403-990-4375 | F5: 30 | G5: 300 | H5: =G5*1.05 -> 315 | I5: $6000/calendar year | J5: Once the annual cap is reached, the deal fee is reduced to $150.00 per transaction for the remainder of the calendar year. | O5: NO | P5: YES
A6: ACTIVE AGENT | B6: Bike | C6: Odigwe Azubike Egwo | D6: odigweazu@gmail.com | E6: (587) 999-2002 | F6: 30 | G6: 300 | H6: =G6*1.05 -> 315 | I6: $6000/calendar year | J6: Once the annual cap is reached, the deal fee is reduced to $150.00 per transaction for the remainder of the calendar year. | O6: NO | P6: YES | Q6: YES | R6: YES | S6: YES
A7: ACTIVE AGENT | B7: Dafe | C7: Dafe Ojevwe | D7: ojesdave@yahoo.com | E7: 587 917 2815 | F7: 30 | G7: 300 | H7: =G7*1.05 -> 315 | I7: $6000/calendar year | J7: Once the annual cap is reached, the deal fee is reduced to $150.00 per transaction for the remainder of the calendar year. | O7: NO | P7: YES | Q7: YES | R7: YES | S7: YES
A8: ACTIVE AGENT | C8: Gurpreet Singh | D8: Gsingh007100@gmail.com | E8: 587-966-9971 | F8: 30 | G8: 300 | H8: =G8*1.05 -> 315 | I8: $6000/calendar year | J8: Once the annual cap is reached, the deal fee is reduced to $150.00 per transaction for the remainder of the calendar year. | O8: YES | P8: YES
A9: NO LONGER AN AGENT | C9: Gurpreet Boparai | D9: preete002@hotmail.com | E9: 825 488 4893 | F9: 30 | G9: $300/per transaction | H9: =G9*1.05 -> #VALUE! | I9: $6000/calendar year | J9: Once the annual cap is reached, the deal fee is reduced to $150.00 per transaction for the remainder of the calendar year.
A10: ACTIVE AGENT | C10: Rishabh Malhotra | D10: rishmalhotra@outlook.com | E10: (587) 973-5223 | F10: 30 | G10: 300 | H10: =G10*1.05 -> 315 | I10: $10,000/calendar year | J10: Once the annual cap is reached, the deal fee is reduced to $100.00 per transaction for the remainder of the calendar year. | O10: YES | P10: NO
A11: IN PENDING | C11: Sameh Osman | D11: osman.sameh@gmail.com | E11: 343-254-1382 | F11: 30 | G11: $300/per transaction | H11: =G11*1.05 -> #VALUE! | I11: $6000/calendar year | J11: Once the annual cap is reached, the deal fee is reduced to $150.00 per transaction for the remainder of the calendar year.
A12: NO LONGER AN AGENT | B12: Habibur Rahman | C12: Md Habibur Rahman | D12: habib85uk@gmail.com | E12: (825) 994-1202 | F12: 30 | G12: 300 | H12: =G12*1.05 -> 315 | I12: $6000/calendar year | J12: Once the annual cap is reached, the deal fee is reduced to $150.00 per transaction for the remainder of the calendar year. | O12: NO | P12: YES
A13: ACTIVE AGENT | B13: Ellie | C13: Minh Anh Pham | D13: elliepham.ca@gmail.com | E13: (403) 888-3311 | F13: 30 | G13: 300 | H13: =G13*1.05 -> 315 | I13: $10,000/calendar year | J13: Once the annual cap is reached, the deal fee is reduced to $100.00 per transaction for the remainder of the calendar year. | O13: YES | P13: YES
A14: ACTIVE AGENT | C14: Sam Nguyen | D14: samnguyen.realtor@gmail.com | E14: 403-826-4569 | F14: 30 | G14: 270 | H14: =G14*1.05 -> 283.5 | I14: $6000/calendar year | J14: Once the annual cap is reached, the deal fee is reduced to $150.00 per transaction for the remainder of the calendar year. | O14: YES | P14: YES | Q14: YES | R14: YES | S14: YES
A15: NO LONGER AN AGENT | C15: Heather Marriot | D15: Hmarriott@shaw.ca | E15: 403 402 6736 | F15: 30 | G15: $300/per transaction | H15: =G15*1.05 -> #VALUE! | I15: $6000/calendar year | J15: Once the annual cap is reached, the deal fee is reduced to $150.00 per transaction for the remainder of the calendar year.
A16: NO LONGER AN AGENT | B16: Shah | C16: Shahab Wasely | D16: waselyshahab@gmail.com | E16: (647)207-8874 | F16: 30 | G16: 300 | H16: =G16*1.05 -> 315 | I16: $10,000/calendar year | J16: Once the annual cap is reached, the deal fee is reduced to $100.00 per transaction for the remainder of the calendar year. | O16: YES | P16: YES
A17: ACTIVE AGENT | B17: Jay | C17: Jawad Wasely | D17: jawad.wasely@gmail.com | E17: (416) 700-8229 | F17: 30 | G17: 300 | H17: =G17*1.05 -> 315 | I17: $10,000/calendar year | J17: Once the annual cap is reached, the deal fee is reduced to $100.00 per transaction for the remainder of the calendar year. | O17: YES | P17: YES
A18: ACTIVE AGENT | C18: Carla Barney | D18: carlabarney@gmail.com | E18: (403) 836-3135 | F18: 30 | G18: 300 | H18: =G18*1.05 -> 315 | I18: $10,000/calendar year | J18: Once the annual cap is reached, the deal fee is reduced to $100.00 per transaction for the remainder of the calendar year. | O18: YES | P18: YES | Q18: YES | R18: YES | S18: YES
A19: ACTIVE AGENT | C19: Rachel Lynn Walia | D19: rachaelwla@icloud.com | E19: (587) 574-8888 | F19: 30 | G19: 250 | H19: =G19*1.05 -> 262.5 | I19: A combined cap of $6,000 per calendar year applies to the two individuals under this plan. | J19: Once the shared $6,000 cap is reached, the deal fee is reduced to $100.00 per transaction for both individuals for the remainder of the calendar year. | O19: YES | P19: YES
A20: ACTIVE AGENT | C20: Amandeep Singh Walia | D20: amanwalia.realtor@gmail.com | E20: (403) 909-9868 | F20: 30 | G20: 250 | H20: =G20*1.05 -> 262.5 | I20: A combined cap of $6,000 per calendar year applies to the two individuals under this plan. | J20: Once the shared $6,000 cap is reached, the deal fee is reduced to $100.00 per transaction for both individuals for the remainder of the calendar year. | O20: YES | P20: YES
A21: ACTIVE AGENT | B21: Antonia | C21: Poh Lian Ee | D21: zacee2025@gmail.com | E21: (825) 994-4228 | F21: 30 | G21: 300 | H21: =G21*1.05 -> 315 | I21: $10,000/calendar year | L21: ● Monthly Fee: $50.00 ● Deal Fee: $500.00 per transaction | M21: ● Monthly Fee: $200.00 ● Deal Fee: $300.00 per transaction capped at $10,000 per calendar year | N21: ● Agents can pick plan 1 or plan 2 individually. ● Team Owner Benefit: Owner(s) of the team will be entitled to 10% of transaction fee as well as 10% of monthly fee which shall be paid by KO Realty every transaction agent from Team closes. (Agents’ monthly and Deal Fee will stay the same). | O21: YES | P21: YES | Q21: YES | R21: NO | S21: YES
A22: NO LONGER AN AGENT | C22: Sherin Thomas | D22: sherin0621@gmail.com | E22: 403-425-5505 | F22: 30 | G22: 250 | H22: =G22*1.05 -> 262.5 | L22: ● Monthly Fee: $50.00 ● Deal Fee: $500.00 per transaction | M22: ● Monthly Fee: $200.00 ● Deal Fee: $300.00 per transaction capped at $10,000 per calendar year | N22: ● Agents can pick plan 1 or plan 2 individually. ● Team Owner Benefit: Owner(s) of the team will be entitled to 10% of transaction fee as well as 10% of monthly fee which shall be paid by KO Realty every transaction agent from Team closes. (Agents’ monthly and Deal Fee will stay the same). | O22: YES | P22: YES | Q22: YES | R22: YES | S22: YES
A23: IN PENDING | C23: Dongyun Kim | D23: kimdy960124@gmail.com | F23: 30 | G23: $300/per transaction | H23: =G23*1.05 -> #VALUE! | I23: $6000/calendar year | J23: Once the annual cap is reached, the deal fee is reduced to $150.00 per transaction for the remainder of the calendar year.
A24: IN PENDING | C24: Mincheol Kwon | D24: kwon7355@gmail.com | E24: 403-862-8258 | F24: 30 | G24: 250 | H24: =G24*1.05 -> 262.5 | I24: $10,000/calendar year | L24: ● Monthly Fee: $50.00 ● Deal Fee: $500.00 per transaction | M24: ● Monthly Fee: $200.00 ● Deal Fee: $300.00 per transaction capped at $10,000 per calendar year | N24: ● Agents can pick plan 1 or plan 2 individually. ● Team Owner Benefit: Owner(s) of the team will be entitled to 10% of transaction fee as well as 10% of monthly fee which shall be paid by KO Realty every transaction agent from Team closes. (Agents’ monthly and Deal Fee will stay the same). | O24: NO | P24: NO | Q24: YES | R24: YES | S24: YES
A25: ACTIVE AGENT | B25: KAY | C25: Kay C Villocillo | D25: realestate.kayc@gmail.com | E25: (587) 222-8175 | H25: =G25*1.05 -> 0 | O25: YES | P25: YES
A26: IN PENDING | C26: Saif Tareen | D26: Saif.tareen@century21.ca | H26: =G26*1.05 -> 0
A27: ACTIVE AGENT | C27: Inkyu Hwang | D27: steve@daonrealty.com | E27: 587-897-2718 | F27: 0 | G27: 100 | H27: =G27*1.05 -> 105 | I27: $10,000/calendar year | O27: NO | P27: NO | Q27: YES | R27: YES | S27: YES
A28: ACTIVE AGENT | C28: Suwoo Lee | D28: SUWOO@daonrealty.com | E28: 403-615-4333 | F28: 0 | G28: 100 | H28: =G28*1.05 -> 105 | I28: $10,000/calendar year | O28: NO | P28: YES | Q28: YES | R28: YES | S28: YES
A29: ACTIVE AGENT | C29: Roxana Diana Velicu | D29: soldbydia@gmail.com | E29: 4034703539 | F29: 30 | G29: 300 | H29: =G29*1.05 -> 315 | I29: $10,000/calendar year | O29: NO | P29: NO | Q29: YES | R29: YES | S29: YES
A30: ACTIVE AGENT | C30: Hemant Akash Persaud | D30: Hemipersaud@gmail.com | E30: (587) 969-4364 | F30: 30 | G30: 300 | H30: =G30*1.05 -> 315 | I30: $10,000/calendar year | O30: NO | P30: NO | Q30: YES | R30: YES | S30: YES
A31: ACTIVE AGENT | C31: Eric Brunetta | D31: Eric@brunetta.ca | E31: (825) 945-9996 | F31: 30 | G31: 300 | H31: =G31*1.05 -> 315 | I31: $10,000/calendar year | O31: NO | P31: YES | Q31: YES | R31: YES | S31: YES
A32: ACTIVE AGENT | B32: Nik | C32: Nikolay Kostov Nikolov | D32: Realtornik@icloud.com | E32: (403) 701-8484 | F32: 30 | G32: 300 | H32: =G32*1.05 -> 315 | I32: $10,000/calendar year | O32: NO | P32: NO | Q32: YES | R32: YES | S32: YES
A33: ACTIVE AGENT | C33: Parwinder Kaur Dhanju | D33: dhanjurealtor@gmail.com | E33: 4034614990 | F33: 30 | G33: 300 | H33: =G33*1.05 -> 315 | I33: $10,000/calendar year | O33: NO | P33: NO | Q33: YES | R33: YES | S33: YES
A34: ACTIVE AGENT | C34: Lorenzo Cabason | D34: l.cabason@gmail.com | E34: MISSING | F34: 30 | G34: 300 | H34: =G34*1.05 -> 315 | I34: $10,000/calendar year | O34: NO | P34: NO | Q34: YES | R34: YES | S34: YES
A35: ACTIVE AGENT | B35: Dolly | C35: Jaspreet Brar | D35: Dollybrar02@gmail.com | E35: 4034834498 | F35: 30 | G35: 300 | H35: =G35*1.05 -> 315 | I35: $10,000/calendar year | O35: YES | P35: NO | Q35: YES | R35: YES | S35: YES
A36: ACTIVE AGENT | C36: Satnam Singh | D36: delightlivinghomes@gmail.com | E36: 4034154175 | F36: 30 | G36: 200 | H36: =G36*1.05 -> 210 | I36: $10,000/calendar year | O36: NO | P36: NO | Q36: YES | R36: YES | S36: YES
A37: ACTIVE AGENT | B37: Ryan | C37: RYAN Suh | D37: ryansuhrealtor@gmail.com | E37: 4034936557 | F37: 0 | G37: 300 | H37: =G37*1.05 -> 315 | I37: $10,000/calendar year | O37: NO | P37: YES | Q37: YES | R37: NO | S37: YES
A38: ACTIVE AGENT | C38: Taranpreet Kaur | D38: soldbytkhomes@gmail.com | E38: 4033971636 | F38: 30 | G38: 300 | H38: =G38*1.05 -> 315 | I38: $10,000/calendar year | O38: YES | P38: NO | Q38: YES | R38: YES | S38: YES
A39: ACTIVE AGENT | C39: Wilson Lleno | D39: wlleno101202@gmail.com | E39: (403) 307-75714 | F39: 30 | G39: 300 | H39: =G39*1.05 -> 315 | I39: $10,000/calendar year | O39: NO | P39: NO | Q39: YES | R39: YES | S39: YES
A40: ACTIVE AGENT | B40: Greg | C40: Gregory Berry | D40: greg@squareonealberta.ca | E40: (403) 402-1500 | F40: 0 | G40: 100 | H40: =G40*1.05 -> 105 | I40: $10,000/calendar year | O40: YES | P40: NO | Q40: YES | R40: YES | S40: YES
...

Sheet SENT PM AGREEMENTS
A1: Management Agreement Date | B1: Service Type | C1: Owner | D1: Property | E1: Assigned PM | F1: Unit # | G1: Assigned Leasing Agent | H1: Occupancy Status | I1: Service Status | J1: Lease Move In | K1: Lease Move out | L1: Leasing Fee | M1: Rent | N1: Pet Fee | O1: Parking | P1: Storage | Q1: Management Fee % | R1: Management Fee | S1: Total Owner Income | T1: Total Owner disbursement | U1: Notes
A2: 46202 | B2: Property Management | C2: Shawn Hari Tomby | D2: 95 Skyview Close Road NE, | E2: Junny Ko | F2: 914 | H2: Vacant | I2: Active | L2: 799 | Q2: 0.07
A3: 46202 | B3: Property Management | C3: Shawn Hari Tomby | D3: 60 Skyview Ranch Road NE | E3: Junny Ko | F3: 3507 | H3: Vacant | I3: Active | L3: 799 | Q3: 0.07
A4: 46202 | B4: Property Management | C4: Shawn Hari Tomby | D4: 111 Wolf Creek Drive SE | E4: Junny Ko | F4: 2408 | H4: Vacant | I4: Active | L4: 799 | Q4: 0.07

Sheet Len-Onboarded
A1: Date Onboarded | B1: Owner | C1: Property | D1: Tenant | E1: Note
A2: 46252 | B2: Siva Nanthan Sunderam | C2: 296 Huxbury View Northeast | D2: Jonna Paramo
A3: 46252 | B3: Liu Yak Ha | E3: tenant lease agreement, property photo, tenant pad form, void cheque
G12: Reminder: Add tenant Hali Marie Lind | H12: 46266
G13: Reminder: Add tenant Hali Marie Lind
